<robot name="air-humanoid">
<link name="pelvis">
<!-- Shapes for pelvis_mesh -->
<collision>
<origin xyz="0.014999999999999871075 -3.1363800445660693961e-17 0.072500000000000008882" rpy="-0.26179929927377443288 4.4408920985006261617e-16 -1.570796326794896558" />
<geometry>
<box size="0.17000000000000001221 0.11999999999999999556 0.11999999999999999556" />
</geometry>
</collision>
<!-- Shapes for rs02 -->
<!-- Shapes for rs02 -->
<visual>
<origin xyz="0 0 0" rpy="0 -0 0" />
<geometry>
<mesh filename="../meshes/pelvis_visual.stl"/>
</geometry>
<material name="pelvis_material">
<color rgba="0.80000000000000004441 0.80000000000000004441 0.80000000000000004441 1.0"/>
</material>
</visual>
<inertial>
<origin xyz="0.0026688269896076146151 -1.9111895622037534932e-09 0.011018541660071061797" rpy="0 0 0"/>
<mass value="1.3501169634884679915" />
<inertia ixx="0.0027682326796764984873" ixy="6.2767277481242875203e-10"  ixz="-0.00017242311995154167262" iyy="0.0022225612832236533653" iyz="-1.576084198589601526e-10" izz="0.0022834983356113309517" />
</inertial>
</link>

<link name="leg_left_hip_pitch">
<!-- Shapes for rs02 -->
<visual>
<origin xyz="0 0 0" rpy="0 -0 0" />
<geometry>
<mesh filename="../meshes/leg_left_hip_pitch_visual.stl"/>
</geometry>
<material name="leg_left_hip_pitch_material">
<color rgba="0.80000000000000004441 0.80000000000000004441 0.80000000000000004441 1.0"/>
</material>
</visual>
<inertial>
<origin xyz="-0.00020438305691359586369 -0.021326929815807645074 -1.2739129677679030247e-18" rpy="0 0 0"/>
<mass value="0.5580110295039465429" />
<inertia ixx="0.0002982384079503413543" ixy="-1.8445063083495326904e-06"  ixz="3.4532655144508366184e-20" iyy="0.00043273780310537195972" iyz="-1.8853334244040710785e-20" izz="0.00030312127594314539547" />
</inertial>
</link>

<link name="leg_left_hip_roll">
<!-- Shapes for rs02 -->
<visual>
<origin xyz="0 0 0" rpy="0 -0 0" />
<geometry>
<mesh filename="../meshes/leg_left_hip_roll_visual.stl"/>
</geometry>
<material name="leg_left_hip_roll_material">
<color rgba="0.80000000000000004441 0.80000000000000004441 0.80000000000000004441 1.0"/>
</material>
</visual>
<inertial>
<origin xyz="1.1575028134572912486e-15 0.081326929815821041858 -0.00020438305691157385375" rpy="0 0 0"/>
<mass value="0.5580110295039465429" />
<inertia ixx="0.00030312127594314550389" ixy="3.0487029432640042313e-18"  ixz="-2.6714140661463257674e-19" iyy="0.00043273780310537152604" iyz="1.844506308366858114e-06" izz="0.0002982384079503418964" />
</inertial>
</link>

<link name="leg_left_hip_yaw">
<!-- Shapes for left_upper_leg_mesh -->
<collision>
<origin xyz="-0.0029999999999626436598 -1.1365713925571834947e-14 -0.12750000000015787593" rpy="-2.1205259770340518321e-14 3.0808688933345620918e-15 -1.4876988529977097642e-14" />
<geometry>
<cylinder length="0.16000000000000000333" radius="0.050000000000000002776" />
</geometry>
</collision>
<visual>
<origin xyz="0 0 0" rpy="0 -0 0" />
<geometry>
<mesh filename="../meshes/leg_left_hip_yaw_visual.stl"/>
</geometry>
<material name="leg_left_hip_yaw_material">
<color rgba="0.80000000000000004441 0.80000000000000004441 0.80000000000000004441 1.0"/>
</material>
</visual>
<inertial>
<origin xyz="-0.0018906454983704176764 -0.0011474285798761464823 -0.12029697121200322307" rpy="0 0 0"/>
<mass value="0.23766371464345470432" />
<inertia ixx="0.00068372898961332659838" ixy="1.1998151223821430049e-05"  ixz="9.6798924417237721426e-06" iyy="0.00065226079185331446546" iyz="-1.5377945175299431913e-05" izz="0.00035655961449075856918" />
</inertial>
</link>

<link name="leg_left_knee">
<!-- Shapes for rs02 -->
<visual>
<origin xyz="0 0 0" rpy="0 -0 0" />
<geometry>
<mesh filename="../meshes/leg_left_knee_visual.stl"/>
</geometry>
<material name="leg_left_knee_material">
<color rgba="0.80000000000000004441 0.80000000000000004441 0.80000000000000004441 1.0"/>
</material>
</visual>
<inertial>
<origin xyz="-0.00020438305691240299736 1.4615899817899422607e-16 0.011326929815805745344" rpy="0 0 0"/>
<mass value="0.5580110295039465429" />
<inertia ixx="0.00029823840795034167956" ixy="-8.8632134884742801764e-21"  ixz="1.8445063083579212812e-06" iyy="0.00030312127594314539547" iyz="5.0700424835480200508e-19" izz="0.00043273780310537195972" />
</inertial>
</link>

<link name="leg_left_ankle_yaw">
<!-- Shapes for rs00 -->
<!-- Shapes for left_lower_leg_mesh -->
<collision>
<origin xyz="-0.0030000000000009879875 -0.0014999999999996127542 0.1399999999999999023" rpy="1.1102230246251458908e-15 -2.2759572004815342258e-15 1.6653345369378578236e-16" />
<geometry>
<cylinder length="0.22000000000000000111" radius="0.03599999999999999728" />
</geometry>
</collision>
<!-- Shapes for rs00 -->
<visual>
<origin xyz="0 0 0" rpy="0 -0 0" />
<geometry>
<mesh filename="../meshes/leg_left_ankle_yaw_visual.stl"/>
</geometry>
<material name="leg_left_ankle_yaw_material">
<color rgba="0.80000000000000015543 0.80000000000000015543 0.80000000000000015543 1.0"/>
</material>
</visual>
<inertial>
<origin xyz="-0.0024030938743459574237 -0.0096053034199410376043 0.16672279056690897381" rpy="0 0 0"/>
<mass value="0.84907497894426264828" />
<inertia ixx="0.0017196608395731020381" ixy="8.2799006535482465816e-07"  ixz="4.8067652708345623034e-05" iyy="0.0017112364790988427235" iyz="9.8150416817905332531e-06" izz="0.00039444938843474780391" />
</inertial>
</link>

<link name="leg_left_ankle_pitch">
<inertial>
<origin xyz="0 0 0" rpy="0 0 0"/>
<mass value="0" />
<inertia ixx="0" ixy="0"  ixz="0" iyy="0" iyz="0" izz="0" />
</inertial>
</link>

<link name="leg_left_feet">
<!-- Shapes for left_feet_mesh -->
<collision>
<origin xyz="0.004000000000010384138 0.042000000000010764833 0.092500000000000401346" rpy="1.57079632679489678 -1.6930901125532763578e-15 1.0547118733938318574e-15" />
<geometry>
<sphere radius="0.010000000000000000208" />
</geometry>
</collision>
<collision>
<origin xyz="0.012000000000010425938 0.048000000000010770163 0.062500000000000416334" rpy="1.57079632679489678 -1.6930901125532763578e-15 1.0547118733938318574e-15" />
<geometry>
<sphere radius="0.010000000000000000208" />
</geometry>
</collision>
<collision>
<origin xyz="-0.015999999999989578114 0.048000000000010742407 0.062500000000000360822" rpy="1.57079632679489678 -1.6930901125532763578e-15 1.0547118733938318574e-15" />
<geometry>
<sphere radius="0.010000000000000000208" />
</geometry>
</collision>
<collision>
<origin xyz="0.0020000000000105627729 0.042000000000010764833 -0.011499999999999614697" rpy="1.57079632679489678 -1.6930901125532763578e-15 1.0547118733938318574e-15" />
<geometry>
<sphere radius="0.016000000000000000333" />
</geometry>
</collision>
<visual>
<origin xyz="0 0 0" rpy="0 -0 0" />
<geometry>
<mesh filename="../meshes/leg_left_feet_visual.stl"/>
</geometry>
<material name="leg_left_feet_material">
<color rgba="0.80000000000000004441 0.80000000000000004441 0.80000000000000004441 1.0"/>
</material>
</visual>
<inertial>
<origin xyz="-0.00056525017299562801965 0.039119939152013352701 0.028105747775491660839" rpy="0 0 0"/>
<mass value="0.15372739596032983234" />
<inertia ixx="0.00017427018814825052983" ixy="-1.1926390131772167467e-07"  ixz="4.3419729719832862364e-06" iyy="0.0001721852359618364337" iyz="-2.2212640915309234813e-05" izz="3.4115600543858722754e-05" />
</inertial>
</link>

<joint name="leg_left_ankle_roll_joint" type="revolute">
<origin xyz="0 0 0" rpy="-1.570796326794896336 -1.5707963267948832353 0" />
<parent link="leg_left_ankle_pitch" />
<child link="leg_left_feet" />
<axis xyz="0 0 1"/>
<limit effort="15" velocity="20" lower="-0.26179938779914940783" upper="0.26179938779914940783"/>
<joint_properties friction="0.0"/>
</joint>

<joint name="leg_left_ankle_pitch_joint" type="revolute">
<origin xyz="-6.9388939039072283776e-18 0 1.1102230246251565404e-16" rpy="-3.4943327596190197446e-17 1.5707963267948845676 0" />
<parent link="leg_left_ankle_yaw" />
<child link="leg_left_ankle_pitch" />
<axis xyz="0 0 1"/>
<limit effort="15" velocity="20" lower="-0.785398163397448279" upper="0.785398163397448279"/>
<joint_properties friction="0.0"/>
</joint>

<joint name="leg_left_ankle_yaw_joint" type="revolute">
<origin xyz="0.29250000000000009326 -0.022499999999999999167 -6.2450045135165055399e-17" rpy="-1.5796939627050750193e-28 -1.5707963267948790165 0" />
<parent link="leg_left_knee" />
<child link="leg_left_ankle_yaw" />
<axis xyz="0 0 1"/>
<limit effort="15" velocity="20" lower="-0.785398163397448279" upper="0.785398163397448279"/>
<joint_properties friction="0.0"/>
</joint>

<joint name="leg_left_knee_pitch_joint" type="revolute">
<origin xyz="0 -9.8607613152626475676e-32 -0.25500000000000000444" rpy="6.8009041934528729891e-31 1.570796326794896558 0" />
<parent link="leg_left_hip_yaw" />
<child link="leg_left_knee" />
<axis xyz="0 0 1"/>
<limit effort="15" velocity="20" lower="-2.356194490192344837" upper="0"/>
<joint_properties friction="0.0"/>
</joint>

<joint name="leg_left_hip_yaw_joint" type="revolute">
<origin xyz="0 -2.9774503199148973655e-31 3.8518598887744717061e-34" rpy="1.570796326794896336 1.2656542480726820848e-14 -6.1232339957379111168e-17" />
<parent link="leg_left_hip_roll" />
<child link="leg_left_hip_yaw" />
<axis xyz="0 0 1"/>
<limit effort="15" velocity="20" lower="-0.785398163397448279" upper="0.785398163397448279"/>
<joint_properties friction="0.0"/>
</joint>

<joint name="leg_left_hip_roll_joint" type="revolute">
<origin xyz="-1.6948183510607675507e-32 2.5038415798651811879e-18 0" rpy="-1.570796326794896336 -1.570796326794896336 0" />
<parent link="leg_left_hip_pitch" />
<child link="leg_left_hip_roll" />
<axis xyz="0 0 1"/>
<limit effort="15" velocity="20" lower="-0.26179938779914940783" upper="0.785398163397448279"/>
<joint_properties friction="0.0"/>
</joint>

<joint name="leg_left_hip_pitch_joint" type="revolute">
<origin xyz="-9.254121991410917654e-26 0.053999999999999999389 2.3980817331903381002e-17" rpy="1.570796326794896558 1.5707963267948947816 0" />
<parent link="pelvis" />
<child link="leg_left_hip_pitch" />
<axis xyz="0 0 1"/>
<limit effort="15" velocity="20" lower="-0.785398163397448279" upper="2.356194490192344837"/>
<joint_properties friction="0.0"/>
</joint>

<link name="leg_right_hip_pitch">
<!-- Shapes for rs02 -->
<visual>
<origin xyz="0 0 0" rpy="0 -0 0" />
<geometry>
<mesh filename="../meshes/leg_right_hip_pitch_visual.stl"/>
</geometry>
<material name="leg_right_hip_pitch_material">
<color rgba="0.80000000000000004441 0.80000000000000004441 0.80000000000000004441 1.0"/>
</material>
</visual>
<inertial>
<origin xyz="-0.00020438305691086700814 -0.02132692981580767283 1.1051973869193503078e-18" rpy="0 0 0"/>
<mass value="0.5580110295039465429" />
<inertia ixx="0.00029823840795034178798" ixy="-1.8445063083667755283e-06"  ixz="1.355268117953901913e-21" iyy="0.00043273780310537152604" iyz="5.119533431643629126e-22" izz="0.00030312127594314539547" />
</inertial>
</link>

<link name="leg_right_hip_roll">
<!-- Shapes for rs02 -->
<visual>
<origin xyz="0 0 0" rpy="0 -0 0" />
<geometry>
<mesh filename="../meshes/leg_right_hip_roll_visual.stl"/>
</geometry>
<material name="leg_right_hip_roll_material">
<color rgba="0.80000000000000004441 0.80000000000000004441 0.80000000000000004441 1.0"/>
</material>
</visual>
<inertial>
<origin xyz="1.0484696930133530205e-18 0.081326929815807663671 -0.0002043830569108898306" rpy="0 0 0"/>
<mass value="0.5580110295039465429" />
<inertia ixx="0.00030312127594314539547" ixy="6.1189774481290659724e-34"  ixz="9.8937807050922920674e-32" iyy="0.00043273780310537152604" iyz="1.8445063083667158125e-06" izz="0.00029823840795034178798" />
</inertial>
</link>

<link name="leg_right_hip_yaw">
<!-- Shapes for right_upper_leg_mesh -->
<collision>
<origin xyz="0.0030000000000000442979 1.0457799598020866805e-31 -0.12750000000000016875" rpy="3.9443045261055144491e-31 -2.627434620609032008e-45 -3.2229864679470772718e-44" />
<geometry>
<cylinder length="0.16000000000000000333" radius="0.050000000000000002776" />
</geometry>
</collision>
<visual>
<origin xyz="0 0 0" rpy="0 -0 0" />
<geometry>
<mesh filename="../meshes/leg_right_hip_yaw_visual.stl"/>
</geometry>
<material name="leg_right_hip_yaw_material">
<color rgba="0.80000000000000004441 0.80000000000000004441 0.80000000000000004441 1.0"/>
</material>
</visual>
<inertial>
<origin xyz="0.0018905204028028047003 -0.0011477205331631285239 -0.12029701413309062952" rpy="0 0 0"/>
<mass value="0.23766122387422336515" />
<inertia ixx="0.00068372406711655528931" ixy="-1.1998358880158732379e-05"  ixz="-9.6779573090535286304e-06" iyy="0.00065225632223770715033" iyz="-1.5377279802580568591e-05" izz="0.00035655642384081780898" />
</inertial>
</link>

<link name="leg_right_knee">
<!-- Shapes for rs02 -->
<visual>
<origin xyz="0 0 0" rpy="0 -0 0" />
<geometry>
<mesh filename="../meshes/leg_right_knee_visual.stl"/>
</geometry>
<material name="leg_right_knee_material">
<color rgba="0.80000000000000004441 0.80000000000000004441 0.80000000000000004441 1.0"/>
</material>
</visual>
<inertial>
<origin xyz="-0.00020438305691094566701 8.3397178091886148667e-18 -0.01132692981580765354" rpy="0 0 0"/>
<mass value="0.5580110295039465429" />
<inertia ixx="0.00029823840795034167956" ixy="-1.1765005725311206253e-33"  ixz="-1.8445063083667598582e-06" iyy="0.00030312127594314539547" iyz="4.4219221313341309271e-35" izz="0.0004327378031053713092" />
</inertial>
</link>

<link name="leg_right_ankle_yaw">
<!-- Shapes for rs00 -->
<!-- Shapes for right_lower_leg_mesh -->
<collision>
<origin xyz="0.0030000000000000096034 -0.0015000000000000013323 0.14000000000000006883" rpy="-1.1247695897932928969e-32 1.7256332301711165914e-31 2.718054075451854338e-44" />
<geometry>
<cylinder length="0.22000000000000000111" radius="0.03599999999999999728" />
</geometry>
</collision>
<!-- Shapes for rs00 -->
<visual>
<origin xyz="0 0 0" rpy="0 -0 0" />
<geometry>
<mesh filename="../meshes/leg_right_ankle_yaw_visual.stl"/>
</geometry>
<material name="leg_right_ankle_yaw_material">
<color rgba="0.80000000000000015543 0.80000000000000015543 0.80000000000000015543 1.0"/>
</material>
</visual>
<inertial>
<origin xyz="0.0024030946194033798655 -0.0096053101042563506645 0.16672278106390586716" rpy="0 0 0"/>
<mass value="0.84907515742371386658" />
<inertia ixx="0.001719662087343171164" ixy="-8.2805816850257973627e-07"  ixz="-4.8067629218004237122e-05" iyy="0.0017112375100648020282" iyz="9.8154600431945485237e-06" izz="0.00039444949497239857562" />
</inertial>
</link>

<link name="leg_right_ankle_pitch">
<inertial>
<origin xyz="0 0 0" rpy="0 0 0"/>
<mass value="0" />
<inertia ixx="0" ixy="0"  ixz="0" iyy="0" iyz="0" izz="0" />
</inertial>
</link>

<link name="leg_right_feet">
<!-- Shapes for right_feet_mesh -->
<collision>
<origin xyz="-0.004000000000000114575 0.041999999999999815259 0.092500000000000026645" rpy="1.57079632679489678 -1.4014411791510214334e-44 0" />
<geometry>
<sphere radius="0.010000000000000000208" />
</geometry>
</collision>
<collision>
<origin xyz="-0.012000000000000114742 0.047999999999999820588 0.062500000000000013878" rpy="1.57079632679489678 -1.4014411791510214334e-44 0" />
<geometry>
<sphere radius="0.010000000000000000208" />
</geometry>
</collision>
<collision>
<origin xyz="0.015999999999999889311 0.047999999999999820588 0.062500000000000013878" rpy="1.57079632679489678 -1.4014411791510214334e-44 0" />
<geometry>
<sphere radius="0.010000000000000000208" />
</geometry>
</collision>
<collision>
<origin xyz="-0.0020000000000001197376 0.041999999999999843014 -0.011499999999999985928" rpy="1.57079632679489678 -1.4014411791510214334e-44 0" />
<geometry>
<sphere radius="0.016000000000000000333" />
</geometry>
</collision>
<visual>
<origin xyz="0 0 0" rpy="0 -0 0" />
<geometry>
<mesh filename="../meshes/leg_right_feet_visual.stl"/>
</geometry>
<material name="leg_right_feet_material">
<color rgba="0.80000000000000004441 0.80000000000000004441 0.80000000000000004441 1.0"/>
</material>
</visual>
<inertial>
<origin xyz="0.0005652521626959630674 0.039119936710207664499 0.028105748366880577843" rpy="0 0 0"/>
<mass value="0.15372738292888285527" />
<inertia ixx="0.00017427017188786654003" ixy="1.1926392062803782247e-07"  ixz="-4.3419719400649356219e-06" iyy="0.00017218521542200054255" iyz="-2.2212637291470558573e-05" izz="3.4115600588668358085e-05" />
</inertial>
</link>

<joint name="leg_right_ankle_roll_joint" type="revolute">
<origin xyz="1.1102230246251565404e-16 1.0408340855860842566e-17 -6.9388939039072283776e-18" rpy="-1.570796326794896336 -1.570796326794896336 0" />
<parent link="leg_right_ankle_pitch" />
<child link="leg_right_feet" />
<axis xyz="0 0 1"/>
<limit effort="15" velocity="20" lower="-0.26179938779914940783" upper="0.26179938779914940783"/>
<joint_properties friction="0.0"/>
</joint>

<joint name="leg_right_ankle_pitch_joint" type="revolute">
<origin xyz="0 -6.9388939039072283776e-18 1.1102230246251565404e-16" rpy="-9.7085368725430385662e-31 1.570796326794896336 0" />
<parent link="leg_right_ankle_yaw" />
<child link="leg_right_ankle_pitch" />
<axis xyz="0 0 1"/>
<limit effort="15" velocity="20" lower="-0.785398163397448279" upper="0.785398163397448279"/>
<joint_properties friction="0.0"/>
</joint>

<joint name="leg_right_ankle_yaw_joint" type="revolute">
<origin xyz="0.29249999999999992673 -0.022499999999999995698 -6.9388939039072283776e-17" rpy="-7.0041171194910210604e-16 -1.5707963267948945596 0" />
<parent link="leg_right_knee" />
<child link="leg_right_ankle_yaw" />
<axis xyz="0 0 1"/>
<limit effort="15" velocity="20" lower="-0.785398163397448279" upper="0.785398163397448279"/>
<joint_properties friction="0.0"/>
</joint>

<joint name="leg_right_knee_pitch_joint" type="revolute">
<origin xyz="-4.1633363423443370266e-17 1.0557947955130826946e-29 -0.25500000000000017097" rpy="4.4195767621494189214e-30 1.570796326794896336 0" />
<parent link="leg_right_hip_yaw" />
<child link="leg_right_knee" />
<axis xyz="0 0 1"/>
<limit effort="15" velocity="20" lower="-2.356194490192344837" upper="0"/>
<joint_properties friction="0.0"/>
</joint>

<joint name="leg_right_hip_yaw_joint" type="revolute">
<origin xyz="4.8572257327350598644e-17 -4.7184478546569152968e-16 1.6767916467813030231e-29" rpy="1.570796326794896336 3.2375344588336235604e-28 2.9582283945787877017e-31" />
<parent link="leg_right_hip_roll" />
<child link="leg_right_hip_yaw" />
<axis xyz="0 0 1"/>
<limit effort="15" velocity="20" lower="-0.785398163397448279" upper="0.785398163397448279"/>
<joint_properties friction="0.0"/>
</joint>

<joint name="leg_right_hip_roll_joint" type="revolute">
<origin xyz="7.4767711785223679523e-18 -2.5533811274267894e-19 0" rpy="-1.570796326794896336 -1.570796326794896336 0" />
<parent link="leg_right_hip_pitch" />
<child link="leg_right_hip_roll" />
<axis xyz="0 0 1"/>
<limit effort="15" velocity="20" lower="-0.785398163397448279" upper="0.26179938779914940783"/>
<joint_properties friction="0.0"/>
</joint>

<joint name="leg_right_hip_pitch_joint" type="revolute">
<origin xyz="-1.2575511642735519166e-30 -0.053999999999999999389 -2.3980817331903381002e-17" rpy="1.570796326794896558 1.5707963267948947816 0" />
<parent link="pelvis" />
<child link="leg_right_hip_pitch" />
<axis xyz="0 0 1"/>
<limit effort="15" velocity="20" lower="-0.785398163397448279" upper="2.356194490192344837"/>
<joint_properties friction="0.0"/>
</joint>

<link name="chest">
<!-- Shapes for rs02 -->
<!-- Shapes for redacted -->
<!-- Shapes for chest_mesh -->
<collision>
<origin xyz="2.3517915736901412347e-31 0.010000000000000000208 0.1624999999999999778" rpy="0.17453270734272877118 -0 8.7581154020301066933e-47" />
<geometry>
<box size="0.14999999999999999445 0.11999999999999999556 0.16000000000000000333" />
</geometry>
</collision>
<!-- Shapes for rs02 -->
<!-- Shapes for rs02 -->
<visual>
<origin xyz="0 0 0" rpy="0 -0 0" />
<geometry>
<mesh filename="../meshes/chest_visual.stl"/>
</geometry>
<material name="chest_material">
<color rgba="0.80000000000000004441 0.80000000000000004441 0.80000000000000004441 1.0"/>
</material>
</visual>
<inertial>
<origin xyz="7.7094204246792094751e-07 -0.0010571905360550048081 0.17142473328233251428" rpy="0 0 0"/>
<mass value="1.8257137134967282854" />
<inertia ixx="0.0095321552043936032261" ixy="-9.2451813156805250082e-08"  ixz="2.7319058123987868814e-08" iyy="0.010684322763926548325" iyz="0.0025107231035734552289" izz="0.0047118962404833920204" />
</inertial>
</link>

<link name="arm_left_shoulder_pitch">
<!-- Shapes for rs02 -->
<visual>
<origin xyz="0 0 0" rpy="0 -0 0" />
<geometry>
<mesh filename="../meshes/arm_left_shoulder_pitch_visual.stl"/>
</geometry>
<material name="arm_left_shoulder_pitch_material">
<color rgba="0.80000000000000004441 0.80000000000000004441 0.80000000000000004441 1.0"/>
</material>
</visual>
<inertial>
<origin xyz="-0.00020438305691077680252 -0.02132692981580767283 -6.1738433635988387463e-18" rpy="0 0 0"/>
<mass value="0.5580110295039465429" />
<inertia ixx="0.00029823840795034178798" ixy="-1.8445063083667755283e-06"  ixz="-1.4447352920596888645e-22" iyy="0.00043273780310537152604" iyz="2.8867084625449743611e-19" izz="0.00030312127594314550389" />
</inertial>
</link>

<link name="arm_left_shoulder_roll">
<!-- Shapes for rs00 -->
<visual>
<origin xyz="0 0 0" rpy="0 -0 0" />
<geometry>
<mesh filename="../meshes/arm_left_shoulder_roll_visual.stl"/>
</geometry>
<material name="arm_left_shoulder_roll_material">
<color rgba="0.80000000000000004441 0.80000000000000004441 0.80000000000000004441 1.0"/>
</material>
</visual>
<inertial>
<origin xyz="-0.00019503843881390220557 0.075629456319792148777 -4.0636062931534312908e-16" rpy="0 0 0"/>
<mass value="0.35350570081958304636" />
<inertia ixx="0.00014852794100576129132" ixy="1.4734391492280701598e-06"  ixz="-1.2142304768542487892e-20" iyy="0.00014496100079901575743" iyz="3.9902533208208843296e-21" izz="0.00015073374843568808075" />
</inertial>
</link>

<link name="arm_left_shoulder_yaw">
<!-- Shapes for left_upper_arm_mesh -->
<collision>
<origin xyz="-0.00099999999994881960674 -1.4536982728685643451e-15 -0.084000000000020669244" rpy="3.1970390994025496298e-16 -3.1297571785675578052e-14 4.4964032497320559604e-15" />
<geometry>
<cylinder length="0.11000000000000000056" radius="0.0240000000000000005" />
</geometry>
</collision>
<!-- Shapes for rs00 -->
<visual>
<origin xyz="0 0 0" rpy="0 -0 0" />
<geometry>
<mesh filename="../meshes/arm_left_shoulder_yaw_visual.stl"/>
</geometry>
<material name="arm_left_shoulder_yaw_material">
<color rgba="0.80000000000000004441 0.80000000000000004441 0.80000000000000004441 1.0"/>
</material>
</visual>
<inertial>
<origin xyz="0.0051370789981285466114 0.00030954912137069452802 -0.14132629809268951182" rpy="0 0 0"/>
<mass value="0.40462950534797564872" />
<inertia ixx="0.00041721930313610663434" ixy="1.9058465372637336284e-06"  ixz="6.8126279797541970367e-06" iyy="0.00042089729341562691096" iyz="-1.0722204200225276467e-05" izz="0.00017344449610804380771" />
</inertial>
</link>

<link name="arm_left_elbow">
<!-- Shapes for rs00 -->
<!-- Shapes for left_lower_arm_mesh -->
<collision>
<origin xyz="0.073999999999999732658 5.5511151231257827021e-17 -0.00099999999999955679897" rpy="-5.5511151231256483492e-17 -1.570796326794896336 0" />
<geometry>
<cylinder length="0.11999999999999999556" radius="0.021999999999999998723" />
</geometry>
</collision>
<visual>
<origin xyz="0 0 0" rpy="0 -0 0" />
<geometry>
<mesh filename="../meshes/arm_left_elbow_visual.stl"/>
</geometry>
<material name="arm_left_elbow_material">
<color rgba="0.80000000000000004441 0.80000000000000004441 0.80000000000000004441 1.0"/>
</material>
</visual>
<inertial>
<origin xyz="0.057552544028704986923 -0.00027148344018835250018 -0.00057552092432093591816" rpy="0 0 0"/>
<mass value="0.3972965668517146054" />
<inertia ixx="0.00015713095037390769899" ixy="-8.2221529776796850933e-07"  ixz="4.8644421467202200021e-06" iyy="0.00021913812817228120748" iyz="-1.0014740906944230679e-07" izz="0.0002175842238606876867" />
</inertial>
</link>

<link name="left_hand">
<!-- Shapes for left_hand_mesh -->
<collision>
<origin xyz="-0.00099999999996236432764 4.0072112295064243881e-15 -0.053999999999995385025" rpy="-9.8532293435478588218e-15 -1.5707963267948801267 0" />
<geometry>
<sphere radius="0.040000000000000000833" />
</geometry>
</collision>
<visual>
<origin xyz="0 0 0" rpy="0 -0 0" />
<geometry>
<mesh filename="../meshes/left_hand_visual.stl"/>
</geometry>
<material name="left_hand_material">
<color rgba="0.80000000000000004441 0.80000000000000004441 0.80000000000000004441 1.0"/>
</material>
</visual>
<inertial>
<origin xyz="-0.0019006806738063319884 0.0029990383592945332389 -0.034086296051455744482" rpy="0 0 0"/>
<mass value="0.068213089059588408181" />
<inertia ixx="4.7771750458082626605e-05" ixy="-2.4660558916591946743e-06"  ixz="-2.5798258453291886636e-06" iyy="3.6649691551581361397e-05" iyz="-2.0292097185568143461e-06" izz="1.5791822499347068072e-05" />
</inertial>
</link>

<joint name="arm_left_wrist_yaw_joint" type="revolute">
<origin xyz="0.14999999999999996669 0 -2.7755575615628913511e-17" rpy="-9.8482095003098587547e-31 -1.5707963267948870101 0" />
<parent link="arm_left_elbow" />
<child link="left_hand" />
<axis xyz="0 0 1"/>
<limit effort="15" velocity="20" lower="-0.785398163397448279" upper="0.785398163397448279"/>
<joint_properties friction="0.0"/>
</joint>

<joint name="arm_left_elbow_pitch_joint" type="revolute">
<origin xyz="4.7184478546569152968e-16 0 -0.15000000000000004996" rpy="9.58456417818011379e-16 1.5707963267948876762 0" />
<parent link="arm_left_shoulder_yaw" />
<child link="arm_left_elbow" />
<axis xyz="0 0 1"/>
<limit effort="15" velocity="20" lower="-0.785398163397448279" upper="0.785398163397448279"/>
<joint_properties friction="0.0"/>
</joint>

<joint name="arm_left_shoulder_yaw_joint" type="revolute">
<origin xyz="-2.7755575615628913511e-17 2.7755575615628913511e-17 0" rpy="1.570796326794896336 7.4222288895831854852e-18 -1.9051709141231696514e-15" />
<parent link="arm_left_shoulder_roll" />
<child link="arm_left_shoulder_yaw" />
<axis xyz="0 0 1"/>
<limit effort="15" velocity="20" lower="-0.785398163397448279" upper="0.785398163397448279"/>
<joint_properties friction="0.0"/>
</joint>

<joint name="arm_left_shoulder_roll_joint" type="revolute">
<origin xyz="0 3.4694469519536141888e-18 0" rpy="-1.5707963267948952257 -1.0471975511965974093 5.2973253724013804362e-16" />
<parent link="arm_left_shoulder_pitch" />
<child link="arm_left_shoulder_roll" />
<axis xyz="0 0 1"/>
<limit effort="15" velocity="20" lower="-1.570796326794896558" upper="1.570796326794896558"/>
<joint_properties friction="0.0"/>
</joint>

<joint name="arm_left_shoulder_pitch_joint" type="revolute">
<origin xyz="-0.066000000000000003109 -0.018000000000000005579 0.21749999999999997113" rpy="-1.5729177094632718635e-31 1.570796326794896336 0" />
<parent link="chest" />
<child link="arm_left_shoulder_pitch" />
<axis xyz="0 0 1"/>
<limit effort="15" velocity="20" lower="-0.785398163397448279" upper="0.785398163397448279"/>
<joint_properties friction="0.0"/>
</joint>

<link name="arm_right_shoulder_pitch">
<!-- Shapes for rs02 -->
<visual>
<origin xyz="0 0 0" rpy="0 -0 0" />
<geometry>
<mesh filename="../meshes/arm_right_shoulder_pitch_visual.stl"/>
</geometry>
<material name="arm_right_shoulder_pitch_material">
<color rgba="0.80000000000000004441 0.80000000000000004441 0.80000000000000004441 1.0"/>
</material>
</visual>
<inertial>
<origin xyz="-0.00020438305691083231367 -0.02132692981580767283 -4.9899609372951316385e-18" rpy="0 0 0"/>
<mass value="0.5580110295039465429" />
<inertia ixx="0.00029823840795034178798" ixy="-1.8445063083667755283e-06"  ixz="-4.2082860575382343038e-23" iyy="0.00043273780310537152604" iyz="2.6464907262283329065e-19" izz="0.00030312127594314507021" />
</inertial>
</link>

<link name="arm_right_shoulder_roll">
<!-- Shapes for rs00 -->
<visual>
<origin xyz="0 0 0" rpy="0 -0 0" />
<geometry>
<mesh filename="../meshes/arm_right_shoulder_roll_visual.stl"/>
</geometry>
<material name="arm_right_shoulder_roll_material">
<color rgba="0.80000000000000004441 0.80000000000000004441 0.80000000000000004441 1.0"/>
</material>
</visual>
<inertial>
<origin xyz="0.00019503843881481586274 0.07562945631979081651 -1.3245132570540318894e-17" rpy="0 0 0"/>
<mass value="0.35350570081958304636" />
<inertia ixx="0.00014852794100576112869" ixy="-1.4734391492280968413e-06"  ixz="3.2716921377149232287e-22" iyy="0.00014496100079901570322" iyz="1.2818074683167248686e-21" izz="0.00015073374843568797233" />
</inertial>
</link>

<link name="arm_right_shoulder_yaw">
<!-- Shapes for right_upper_arm_mesh -->
<collision>
<origin xyz="0.0010000000000000008882 4.8572257327350598644e-17 -0.083999999999999908074" rpy="-3.141592653589793116 -3.381053063611551042e-17 -3.141592653589793116" />
<geometry>
<cylinder length="0.11000000000000000056" radius="0.0240000000000000005" />
</geometry>
</collision>
<!-- Shapes for rs00 -->
<visual>
<origin xyz="0 0 0" rpy="0 -0 0" />
<geometry>
<mesh filename="../meshes/arm_right_shoulder_yaw_visual.stl"/>
</geometry>
<material name="arm_right_shoulder_yaw_material">
<color rgba="0.80000000000000004441 0.80000000000000004441 0.80000000000000004441 1.0"/>
</material>
</visual>
<inertial>
<origin xyz="-0.0051370790630916596253 0.00030954942406503840185 -0.14132629506424726484" rpy="0 0 0"/>
<mass value="0.40462954751480234572" />
<inertia ixx="0.00041721932713668940552" ixy="-1.9058146956620893134e-06"  ixz="-6.812669437738909191e-06" iyy="0.00042089731913521179294" iyz="-1.0722198774158843684e-05" izz="0.00017344450150979368302" />
</inertial>
</link>

<link name="arm_right_elbow">
<!-- Shapes for right_lower_arm_mesh -->
<collision>
<origin xyz="0.073999999999938448347 2.8893554215869698965e-14 0.0010000000001134656813" rpy="-1.6375789613221084215e-14 1.5707963267948354957 0" />
<geometry>
<cylinder length="0.11999999999999999556" radius="0.021999999999999998723" />
</geometry>
</collision>
<!-- Shapes for rs00 -->
<visual>
<origin xyz="0 0 0" rpy="0 -0 0" />
<geometry>
<mesh filename="../meshes/arm_right_elbow_visual.stl"/>
</geometry>
<material name="arm_right_elbow_material">
<color rgba="0.80000000000000004441 0.80000000000000004441 0.80000000000000004441 1.0"/>
</material>
</visual>
<inertial>
<origin xyz="0.057552544468022534541 -0.00027148415566605860715 0.00057551841170496570704" rpy="0 0 0"/>
<mass value="0.3972965308987254085" />
<inertia ixx="0.00015713093246479063855" ixy="-8.2222193823398406605e-07"  ixz="-4.8644382834556525064e-06" iyy="0.0002191381525054683112" iyz="1.0015678170324600861e-07" izz="0.00021758423850443554381" />
</inertial>
</link>

<link name="right_hand">
<!-- Shapes for right_hand_mesh -->
<collision>
<origin xyz="0.00099999999996658317514 -2.1808943539980418791e-14 -0.053999999999982672971" rpy="-2.2204460492534552124e-16 1.5707963267948461539 0" />
<geometry>
<sphere radius="0.040000000000000000833" />
</geometry>
</collision>
<visual>
<origin xyz="0 0 0" rpy="0 -0 0" />
<geometry>
<mesh filename="../meshes/right_hand_visual.stl"/>
</geometry>
<material name="right_hand_material">
<color rgba="0.80000000000000004441 0.80000000000000004441 0.80000000000000004441 1.0"/>
</material>
</visual>
<inertial>
<origin xyz="0.0019006820518614466701 0.0029990385943036820988 -0.034086290519180328928" rpy="0 0 0"/>
<mass value="0.068213107958726190705" />
<inertia ixx="4.7771765912497528273e-05" ixy="2.4660559431355569774e-06"  ixz="2.5798234173530793142e-06" iyy="3.6649702764986030452e-05" iyz="-2.0292100150013645686e-06" izz="1.5791825042012148293e-05" />
</inertial>
</link>

<joint name="arm_right_wrist_yaw_joint" type="revolute">
<origin xyz="0.14999999999999769074 3.4694469519536141888e-18 -1.3877787807814456755e-16" rpy="-1.3808453847752483308e-31 -1.570796326794891673 0" />
<parent link="arm_right_elbow" />
<child link="right_hand" />
<axis xyz="0 0 1"/>
<limit effort="15" velocity="20" lower="-0.785398163397448279" upper="0.785398163397448279"/>
<joint_properties friction="0.0"/>
</joint>

<joint name="arm_right_elbow_pitch_joint" type="revolute">
<origin xyz="-8.3266726846886740532e-17 0 -0.14999999999999999445" rpy="-2.1372674594763257107e-18 1.5707963267948941155 0" />
<parent link="arm_right_shoulder_yaw" />
<child link="arm_right_elbow" />
<axis xyz="0 0 1"/>
<limit effort="15" velocity="20" lower="-0.785398163397448279" upper="0.785398163397448279"/>
<joint_properties friction="0.0"/>
</joint>

<joint name="arm_right_shoulder_yaw_joint" type="revolute">
<origin xyz="0 2.7755575615628913511e-17 0" rpy="1.570796326794896336 -5.923750470296498874e-15 -1.1874347964521361147e-15" />
<parent link="arm_right_shoulder_roll" />
<child link="arm_right_shoulder_yaw" />
<axis xyz="0 0 1"/>
<limit effort="15" velocity="20" lower="-0.785398163397448279" upper="0.785398163397448279"/>
<joint_properties friction="0.0"/>
</joint>

<joint name="arm_right_shoulder_roll_joint" type="revolute">
<origin xyz="4.4408920985006261617e-16 0 1.9428902930940239457e-16" rpy="1.5707963267948958919 -1.0471975511965982975 -3.1415926535897908956" />
<parent link="arm_right_shoulder_pitch" />
<child link="arm_right_shoulder_roll" />
<axis xyz="0 0 1"/>
<limit effort="15" velocity="20" lower="-1.570796326794896558" upper="1.570796326794896558"/>
<joint_properties friction="0.0"/>
</joint>

<joint name="arm_right_shoulder_pitch_joint" type="revolute">
<origin xyz="0.066000000000000016986 -0.017999999999999988232 0.21750000000000002665" rpy="-6.9714611098467086935e-32 1.570796326794896336 0" />
<parent link="chest" />
<child link="arm_right_shoulder_pitch" />
<axis xyz="0 0 1"/>
<limit effort="15" velocity="20" lower="-0.785398163397448279" upper="0.785398163397448279"/>
<joint_properties friction="0.0"/>
</joint>

<link name="head">
<!-- Shapes for rs00 -->
<!-- Shapes for head_mesh -->
<collision>
<origin xyz="0 -2.8201777361651175196e-31 0.063000000000000055955" rpy="0 -0 1.7516230804060213387e-46" />
<geometry>
<sphere radius="0.080000000000000001665" />
</geometry>
</collision>
<visual>
<origin xyz="0 0 0" rpy="0 -0 0" />
<geometry>
<mesh filename="../meshes/head_visual.stl"/>
</geometry>
<material name="head_material">
<color rgba="0.80000000000000004441 0.80000000000000004441 0.80000000000000004441 1.0"/>
</material>
</visual>
<inertial>
<origin xyz="4.078287564869576071e-08 0.0021472489008166678257 0.00074209610360344009476" rpy="0 0 0"/>
<mass value="0.38902069422263652054" />
<inertia ixx="0.00035299447240395295322" ixy="-5.8981642112206896282e-10"  ixz="1.4886641381563245771e-09" iyy="0.00036852805930219739543" iyz="-4.579037130075447261e-05" izz="0.00022677465825653701391" />
</inertial>
</link>

<joint name="neck_yaw_joint" type="revolute">
<origin xyz="-1.9894085953542392168e-31 -7.1983557601417303597e-32 0.2999999999999999889" rpy="-1.9721522630525295135e-31 -0 -5.0132886437559447427e-30" />
<parent link="chest" />
<child link="head" />
<axis xyz="0 0 1"/>
<limit effort="15" velocity="20" lower="-0.785398163397448279" upper="0.785398163397448279"/>
<joint_properties friction="0.0"/>
</joint>

<joint name="waist_yaw_joint" type="revolute">
<origin xyz="-1.0658141036401488835e-16 -2.664535259100376831e-17 0.05999999999999999778" rpy="1.7763568394002486897e-15 4.4408920985006261617e-16 -1.570796326794896558" />
<parent link="pelvis" />
<child link="chest" />
<axis xyz="0 0 1"/>
<limit effort="15" velocity="20" lower="-0.785398163397448279" upper="0.785398163397448279"/>
<joint_properties friction="0.0"/>
</joint>


</robot>
